Workbook

Sheet 스킬데이터
A1: 계열 | B1: 직업 | C1: 스킬명 | D1: 차수 | E1: 구분 | F1: 쿨타임(초) | G1: 지속시간(초) | H1: 지속시간2(초) | I1: 계수(1레벨) | J1: 타수 | K1: 대상수 | L1: 마스터리 | M1: 세부내용
A2: 전사 | B2: 팔라딘 | C2: 아이언바디 | D2: 1차 | E2: 패시브 | L2: 방어력 증가량 10%P 증가 | M2: STR 30, 방어력 15% 증가
A3: 전사 | B3: 팔라딘 | C3: 워리어 마스터리 | D3: 1차 | E3: 패시브 | L3: 이동 속도 증가량 5%P 증가 | M3: 최대 HP10%, 이동속도 10% 증가
A4: 전사 | B4: 팔라딘 | C4: 웨폰 액셀레이션 | D4: 2차 | E4: 패시브 | M4: 공격 속도 5% 증가
A5: 전사 | B5: 팔라딘 | C5: 페이지 오더 | D5: 2차 | E5: 액티브 | F5: 18 | I5: 4.6 | L5: 페이지 오더 피해량 50% 증가, 페이지 오더에 피해입은 적 10초간 받는 피해 10% 증가
A6: 전사 | B6: 팔라딘 | C6: 피지컬 트레이닝 | D6: 2차 | E6: 패시브 | M6: 기본 공격 데미지 10% 증가
A7: 전사 | B7: 팔라딘 | C7: 스탠스 | D7: 2차 | E7: 패시브 | M7: 받는 피해 3% 감소, 공격력 8% 증가
A8: 전사 | B8: 팔라딘 | C8: 웨폰 마스터리 | D8: 2차 | E8: 패시브 | M8: 최소 데미지 배율 15% 증가
A9: 전사 | B9: 팔라딘 | C9: 홀리 차지 | D9: 2차 | E9: 패시브 | G9: 10 | L9: 홀리 차지 공격력 증가량 5%P 증가 | M9: 기본 공격 시 15% 확률로 10초간 공격력 15% 증가
A10: 전사 | B10: 팔라딘 | C10: 파이널 어택 | D10: 2차 | E10: 패시브 | L10: 파이널 어택 피해량 50% 증가 | M10: 공격 시 25% 확률로 파이널 어택 발동하여 35% 추가 피해
A11: 전사 | B11: 팔라딘 | C11: 아킬레스 | D11: 3차 | E11: 패시브 | M11: 받는 피해 6% 감소, 디버프 내성 5 증가
A12: 전사 | B12: 팔라딘 | C12: 돌진 | D12: 3차 | E12: 액티브 | F12: 22 | I12: 6 | L12: 돌진 피해량 80% 증가, 돌진 재사용 대기시간 30% 감소 | M12: 상대방 2.5초 기절
A13: 전사 | B13: 팔라딘 | C13: 노블 디맨드 | D13: 3차 | E13: 액티브 | F13: 30 | G13: 10 | I13: 16 | L13: 노블 디멘드 피해량 50% 증가, 노블 디맨드 재사용 대기시간 30% 감소 | M13: 10초간 상대방 받는 피해 12% 증가
A14: 전사 | B14: 팔라딘 | C14: 컴뱃 오더스 | D14: 3차 | E14: 액티브 | F14: 35 | G14: 25 | L14: 컴뱃 오더스 지속시간 동안 데미지 25%P 증가, 컴뱃 오더스 지속시간 동안 4차 스킬 레벨 18 증가 | M14: 25초간 3차 스킬레벨18 증가, MP소모량 20% 감소
A15: 전사 | B15: 팔라딘 | C15: 파라쇼크 가드 | D15: 3차 | E15: 패시브 | L15: 공격력 증가량 10%P 증가 | M15: 공격력 18% 증가
A16: 전사 | B16: 팔라딘 | C16: 리스토네이션 | D16: 3차 | E16: 액티브 | F16: 25 | G16: 20 | L16: 리스토네이션 공격력 증가량 10%P 증가 | M16: HP 9% 즉시 회복, 20초간 공격력 12% 증가
A17: 전사 | B17: 팔라딘 | C17: 블레싱 아머 | D17: 3차 | E17: 패시브 | G17: 5 | H17: 10 | M17: 15초마다 5초간 지속되는 보호막 생성하여 최대 HP의 6% 만큼 피해 방어, 10초간 최종 데미지가 15% 증가
A18: 전사 | B18: 팔라딘 | C18: 블래스트 | D18: 4차 | E18: 기본공격 | I18: 2.9 | J18: 5 | L18: 블래스트 피해량 75% 증가, 보스 몬스터 데미지 20% 추가 적용, 적 타격 횟수 1 증가 | M18: 스킬타수 5회
A19: 전사 | B19: 팔라딘 | C19: 메이플용사 | D19: 4차 | E19: 패시브 | M19: 노블 디맨드 20%, 돌진 30%, 페이지 오더 80%, 파이널 어택 150% 최종데미지 증가
A20: 전사 | B20: 팔라딘 | C20: 생츄어리 | D20: 4차 | E20: 액티브 | F20: 18 | I20: 7.8 | J20: 5 | L20: 생츄어리 피해량 50% 증가, 보스 몬스터 데미지 100% 추가 적용 | M20: 스킬타수 5회, 보스 몬스터 데미지 100% 추가 적용
A21: 전사 | B21: 팔라딘 | C21: 가디언 스피릿 | D21: 4차 | E21: 액티브 | F21: 24 | G21: 20 | L21: 지속시간 동안 아군 받는 피해 5% 감소 | M21: 20초간 최종 데미지 10% 증가
A22: 전사 | B22: 팔라딘 | C22: 디바인 스티그마 | D22: 4차 | E22: 액티브 | F22: 16 | I22: 4.6 | J22: 6 | L22: 디바인 스티그마 피해량 50% 증가, 피해입은 적 10초간 받는 피해 20% 증가 | M22: 스킬타수 6회, 성흔을 남기고 성흔은 주변 적 400% 피해를 4회 입힘
A23: 전사 | B23: 팔라딘 | C23: 어드밴스드 홀리 차지 | D23: 4차 | E23: 패시브 | L23: 어드밴스드 홀리 차지 최종 데미지 10%P 증가 | M23: 홀리 차지 지속시간 동안 최종 데미지 18% 증가
A24: 전사 | B24: 팔라딘 | C24: 디바인 블레싱 | D24: 4차 | E24: 액티브 | F24: 30 | G24: 22 | L24: 디바인 블레싱 최종 데미지 12%P 증가 | M24: 22초간 최종 데미지 12% 증가
A25: 전사 | B25: 팔라딘 | C25: 매직 크래쉬 | D25: 4차 | E25: 액티브 | F25: 28 | I25: 48
A26: 전사 | B26: 팔라딘 | C26: 팔라딘 엑스퍼트 | D26: 4차 | E26: 패시브 | M26: 스킬 데미지 15%, 최대 데미지 배율 20% 증가
A27: 전사 | B27: 팔라딘 | C27: 디바인 저지먼트 | D27: 4차 | E27: 패시브 | G27: 5 | I27: 8.5 | J27: 4 | L27: 디바인 저지먼트 피해량 50% 증가 | M27: 스킬타수 4회, 기본 공격 효과 스킬을 10회 사용할때마다 5초간 기본 공격 데미지 30% 증가
A28: 전사 | B28: 히어로 | C28: 아이언바디 | D28: 1차 | E28: 패시브 | L28: 아이언 바디 방어력 증가량 10%p 증가 | M28: STR 30, 방어력 15% 증가
A29: 전사 | B29: 히어로 | C29: 워리어 마스터리 | D29: 1차 | E29: 패시브 | L29: 워리어 마스터리 이동 속도 증가량 5%p 증가 | M29: 최대 HP10%, 이동속도 10% 증가
A30: 전사 | B30: 히어로 | C30: 웨폰 액셀레이션 | D30: 2차 | E30: 패시브 | M30: 공격 속도 5% 증가
A31: 전사 | B31: 히어로 | C31: 플래시 슬래시 | D31: 2차 | E31: 액티브 | F31: 16 | I31: 3.5 | J31: 1 | K31: 7 | L31: 플래시 슬래시 피해량 50% 증가
A32: 전사 | B32: 히어로 | C32: 피지컬 트레이닝 | D32: 2차 | E32: 패시브 | M32: 기본 공격 데미지 10% 증가
A33: 전사 | B33: 히어로 | C33: 스피릿 블레이드 | D33: 2차 | E33: 액티브 | F33: 45 | G33: 20 | L33: 스피릿 블레이드 재사용 대기시간 30% 감소 | M33: 20초간 받는 피해 8% 감소, 아군 플레이어 공격력 10% 증가
A34: 전사 | B34: 히어로 | C34: 웨폰 마스터리 | D34: 2차 | E34: 패시브 | M34: 최소 데미지 배율 15% 증가
A35: 전사 | B35: 히어로 | C35: 콤보 어택 | D35: 2차 | E35: 패시브 | G35: 10 | L35: 콤보 어택 공격력 증가량 1.5%p 증가 | M35: 공격 시 40% 확률로 10초간 공격력 4% 증가, 최대 5회 중첩
A36: 전사 | B36: 히어로 | C36: 파이널 어택 | D36: 2차 | E36: 패시브 | L36: 파이널 어택 피해량 50% 증가 | M36: 공격 시 25% 확률로 파이널 어택 발동하여 35% 추가 피해
A37: 전사 | B37: 히어로 | C37: 셀프 리커버리 | D37: 3차 | E37: 패시브 | L37: HP 50% 이상일 때 최종 데미지 5% 증가 | M37: 매초 HP 1%, MP 0.5% 회복
A38: 전사 | B38: 히어로 | C38: 돌진 | D38: 3차 | E38: 액티브 | F38: 22 | I38: 6 | J38: 1 | K38: 12 | L38: 돌진 피해량 80% 증가, 돌진 재사용 대기시간 30% 감소 | M38: 상대방 2.5초 기절
A39: 전사 | B39: 히어로 | C39: 스카링 소드 | D39: 3차 | E39: 액티브 | F39: 30 | G39: 15 | H39: 10 | L39: 스카링 소드 받는 피해 증가량 8%p 증가 | M39: 15초간 35% 확률로 10초간 대상 공격력 10% 감소, 대상 받는 피해 20% 증가
A40: 전사 | B40: 히어로 | C40: 오라 블레이드 | D40: 3차 | E40: 액티브 | F40: 16 | I40: 2.5 | J40: 4 | K40: 8 | L40: 오라 블레이드 피해량 50% 증가, 오라 블레이드 적 타격 횟수 1 증가, 오라 블레이드 재사용 대기시간 30% 감소 | M40: 스킬 타수 4회
...

Sheet 기준·현황
A1: 📋 수집 기준 (확정 2026-08-08)
A2: 1. 스킬 계수는 전 스킬 1레벨 기준으로 수집 — 직업 간 비교·밸런스 랭킹 기준선
A3: (본인 딜 계산은 본인 계수를 따로 입력, 1레벨 값으로 대체하지 않음)
A4: 2. 타수 = 1회 시전에 몇 번 때리는가 / 대상수 = 몇 명을 때리는가 — 별개 컬럼
A5: 3. 쿨타임·지속시간은 숫자만(초). 지속 효과가 2개인 스킬은 지속시간2에 두 번째 값
A6: 4. 기절·빙결 등 CC 시간은 지속시간에 넣지 않음 (세부내용에만)
A7: 5. 아래 전직업 공통 마스터리 7종은 스탯창에 이미 적용 기준 → 시트에 적지 않음
A8: 6. 마스터리는 쿨감 / 버프 강화 / 스킬 피해량 / 타격 횟수·보스뎀 4종류만 수집
A10: 🚫 전직업 공통 마스터리 7종 (스탯창 기적용 — 수집 제외)
A11: · 기본 공격 데미지 15% 증가
A12: · 기본 공격 대상 수 1 증가
A13: · 최대 데미지 배율 10% 증가
... A19: 📊 직업별 수집 현황 (자동 집계)
A20: 계열 | B20: 직업 | C20: 주스탯 | D20: 부스탯 | E20: 스킬 수 | F20: 쿨타임 입력 | G20: 마스터리 입력 | H20: 계수 입력
A21: 전사 | B21: 히어로 | C21: STR | D21: DEX | E21: =COUNTIF(스킬데이터!$B:$B,$B21) -> 26 | F21: =COUNTIFS(스킬데이터!$B:$B,$B21,스킬데이터!$F:$F,"<>") -> 8 | G21: =COUNTIFS(스킬데이터!$B:$B,$B21,스킬데이터!$L:$L,"<>") -> 17 | H21: =COUNTIFS(스킬데이터!$B:$B,$B21,스킬데이터!$I:$I,"<>") -> 7
A22: 전사 | B22: 팔라딘 | C22: STR | D22: DEX | E22: =COUNTIF(스킬데이터!$B:$B,$B22) -> 26 | F22: =COUNTIFS(스킬데이터!$B:$B,$B22,스킬데이터!$F:$F,"<>") -> 10 | G22: =COUNTIFS(스킬데이터!$B:$B,$B22,스킬데이터!$L:$L,"<>") -> 17 | H22: =COUNTIFS(스킬데이터!$B:$B,$B22,스킬데이터!$I:$I,"<>") -> 8
A23: 전사 | B23: 다크나이트 | C23: STR | D23: DEX | E23: =COUNTIF(스킬데이터!$B:$B,$B23) -> 26 | F23: =COUNTIFS(스킬데이터!$B:$B,$B23,스킬데이터!$F:$F,"<>") -> 10 | G23: =COUNTIFS(스킬데이터!$B:$B,$B23,스킬데이터!$L:$L,"<>") -> 17 | H23: =COUNTIFS(스킬데이터!$B:$B,$B23,스킬데이터!$I:$I,"<>") -> 7
A24: 법사 | B24: 불독 | C24: INT | D24: LUK | E24: =COUNTIF(스킬데이터!$B:$B,$B24) -> 25 | F24: =COUNTIFS(스킬데이터!$B:$B,$B24,스킬데이터!$F:$F,"<>") -> 0 | G24: =COUNTIFS(스킬데이터!$B:$B,$B24,스킬데이터!$L:$L,"<>") -> 1 | H24: =COUNTIFS(스킬데이터!$B:$B,$B24,스킬데이터!$I:$I,"<>") -> 8
A25: 법사 | B25: 썬콜 | C25: INT | D25: LUK | E25: =COUNTIF(스킬데이터!$B:$B,$B25) -> 25 | F25: =COUNTIFS(스킬데이터!$B:$B,$B25,스킬데이터!$F:$F,"<>") -> 0 | G25: =COUNTIFS(스킬데이터!$B:$B,$B25,스킬데이터!$L:$L,"<>") -> 1 | H25: =COUNTIFS(스킬데이터!$B:$B,$B25,스킬데이터!$I:$I,"<>") -> 8
A26: 법사 | B26: 비숍 | C26: INT | D26: LUK | E26: =COUNTIF(스킬데이터!$B:$B,$B26) -> 25 | F26: =COUNTIFS(스킬데이터!$B:$B,$B26,스킬데이터!$F:$F,"<>") -> 0 | G26: =COUNTIFS(스킬데이터!$B:$B,$B26,스킬데이터!$L:$L,"<>") -> 1 | H26: =COUNTIFS(스킬데이터!$B:$B,$B26,스킬데이터!$I:$I,"<>") -> 5
A27: 도적 | B27: 나이트로드 | C27: LUK | D27: DEX | E27: =COUNTIF(스킬데이터!$B:$B,$B27) -> 25 | F27: =COUNTIFS(스킬데이터!$B:$B,$B27,스킬데이터!$F:$F,"<>") -> 8 | G27: =COUNTIFS(스킬데이터!$B:$B,$B27,스킬데이터!$L:$L,"<>") -> 17 | H27: =COUNTIFS(스킬데이터!$B:$B,$B27,스킬데이터!$I:$I,"<>") -> 8
A28: 도적 | B28: 섀도어 | C28: LUK | D28: DEX | E28: =COUNTIF(스킬데이터!$B:$B,$B28) -> 26 | F28: =COUNTIFS(스킬데이터!$B:$B,$B28,스킬데이터!$F:$F,"<>") -> 0 | G28: =COUNTIFS(스킬데이터!$B:$B,$B28,스킬데이터!$L:$L,"<>") -> 1 | H28: =COUNTIFS(스킬데이터!$B:$B,$B28,스킬데이터!$I:$I,"<>") -> 10
A29: 궁수 | B29: 보우마스터 | C29: DEX | D29: STR | E29: =COUNTIF(스킬데이터!$B:$B,$B29) -> 26 | F29: =COUNTIFS(스킬데이터!$B:$B,$B29,스킬데이터!$F:$F,"<>") -> 0 | G29: =COUNTIFS(스킬데이터!$B:$B,$B29,스킬데이터!$L:$L,"<>") -> 1 | H29: =COUNTIFS(스킬데이터!$B:$B,$B29,스킬데이터!$I:$I,"<>") -> 4
A30: 궁수 | B30: 신궁 | C30: DEX | D30: STR | E30: =COUNTIF(스킬데이터!$B:$B,$B30) -> 26 | F30: =COUNTIFS(스킬데이터!$B:$B,$B30,스킬데이터!$F:$F,"<>") -> 0 | G30: =COUNTIFS(스킬데이터!$B:$B,$B30,스킬데이터!$L:$L,"<>") -> 1 | H30: =COUNTIFS(스킬데이터!$B:$B,$B30,스킬데이터!$I:$I,"<>") -> 7
A31: 해적 | B31: 바이퍼 | C31: STR | D31: DEX | E31: =COUNTIF(스킬데이터!$B:$B,$B31) -> 25 | F31: =COUNTIFS(스킬데이터!$B:$B,$B31,스킬데이터!$F:$F,"<>") -> 6 | G31: =COUNTIFS(스킬데이터!$B:$B,$B31,스킬데이터!$L:$L,"<>") -> 17 | H31: =COUNTIFS(스킬데이터!$B:$B,$B31,스킬데이터!$I:$I,"<>") -> 8
A32: 해적 | B32: 캡틴 | C32: STR | D32: DEX | E32: =COUNTIF(스킬데이터!$B:$B,$B32) -> 25 | F32: =COUNTIFS(스킬데이터!$B:$B,$B32,스킬데이터!$F:$F,"<>") -> 0 | G32: =COUNTIFS(스킬데이터!$B:$B,$B32,스킬데이터!$L:$L,"<>") -> 1 | H32: =COUNTIFS(스킬데이터!$B:$B,$B32,스킬데이터!$I:$I,"<>") -> 11
... A34: 시그너스 | B34: 나이트워커 | C34: LUK | D34: DEX | E34: =COUNTIF(스킬데이터!$B:$B,$B34) -> 25 | F34: =COUNTIFS(스킬데이터!$B:$B,$B34,스킬데이터!$F:$F,"<>") -> 7 | G34: =COUNTIFS(스킬데이터!$B:$B,$B34,스킬데이터!$L:$L,"<>") -> 16 | H34: =COUNTIFS(스킬데이터!$B:$B,$B34,스킬데이터!$I:$I,"<>") -> 5
